We fixed a bug that caused a "Bad file descriptor" error from the python
operator, when multiple instances of it were started simultaneously.
